from django.forms import ValidationError
from django.test import TestCase
from .models import CustomUser
from .validators import SpecialCharacterPasswordValidator


class CustomUserValidatorTest(TestCase):

    def setUp(self):
        self.validator = SpecialCharacterPasswordValidator()
        self.valid_password_cases = [
            "StrongP@ssw0rd",
            "Another#Pass123",
            "Passw0rd!",
            "1234Abc#1234",
            "Complex$Password1",
            "ValidPassword2024!",
        ]

        self.invalid_password_cases = [
            "password",
            "12345678",
            "PASSWORD",
            "short",
            "nouppercase123@",
            "NOLOWERCASE123@",
            "NoSpecialChar123",
            " space in pass ",
            "repeated!!repeated!!",
        ]

    def test_valid_passwords(self):
        for password in self.valid_password_cases:
            with self.subTest(password=password):
                try:
                    self.validator.validate(password)
                except ValidationError:
                    self.fail(
                        f"Valid password '{password}' raised ValidationError unexpectedly."
                    )

    def test_invalid_passwords(self):
        for invalid_password in self.invalid_password_cases:
            with self.subTest(invalid_password=invalid_password):
                with self.assertRaises(ValidationError):
                    self.validator.validate(invalid_password)
